[2023-03-21 08:23:47,676] {taskinstance.py:1032} INFO - Dependencies all met for <TaskInstance: querry_postgres_v1.4.create_querry_postgres_table manual__2023-03-21T07:52:34.606843+00:00 [queued]>
[2023-03-21 08:23:47,716] {taskinstance.py:1032} INFO - Dependencies all met for <TaskInstance: querry_postgres_v1.4.create_querry_postgres_table manual__2023-03-21T07:52:34.606843+00:00 [queued]>
[2023-03-21 08:23:47,717] {taskinstance.py:1238} INFO - 
--------------------------------------------------------------------------------
[2023-03-21 08:23:47,718] {taskinstance.py:1239} INFO - Starting attempt 7 of 8
[2023-03-21 08:23:47,719] {taskinstance.py:1240} INFO - 
--------------------------------------------------------------------------------
[2023-03-21 08:23:47,758] {taskinstance.py:1259} INFO - Executing <Task(PostgresOperator): create_querry_postgres_table> on 2023-03-21 07:52:34.606843+00:00
[2023-03-21 08:23:47,766] {standard_task_runner.py:52} INFO - Started process 259 to run task
[2023-03-21 08:23:47,778] {standard_task_runner.py:76} INFO - Running: ['***', 'tasks', 'run', 'querry_postgres_v1.4', 'create_querry_postgres_table', 'manual__2023-03-21T07:52:34.606843+00:00', '--job-id', '268', '--raw', '--subdir', 'DAGS_FOLDER/querry_posgresql.py', '--cfg-path', '/tmp/tmpqy7iak9h', '--error-file', '/tmp/tmp4bno2pgl']
[2023-03-21 08:23:47,781] {standard_task_runner.py:77} INFO - Job 268: Subtask create_querry_postgres_table
[2023-03-21 08:23:48,105] {logging_mixin.py:109} INFO - Running <TaskInstance: querry_postgres_v1.4.create_querry_postgres_table manual__2023-03-21T07:52:34.606843+00:00 [running]> on host 0b4cdb459521
[2023-03-21 08:23:48,441] {taskinstance.py:1426} INFO - Exporting the following env vars:
AIRFLOW_CTX_DAG_OWNER=sakabuana31
AIRFLOW_CTX_DAG_ID=querry_postgres_v1.4
AIRFLOW_CTX_TASK_ID=create_querry_postgres_table
AIRFLOW_CTX_EXECUTION_DATE=2023-03-21T07:52:34.606843+00:00
AIRFLOW_CTX_DAG_RUN_ID=manual__2023-03-21T07:52:34.606843+00:00
[2023-03-21 08:23:48,521] {base.py:79} INFO - Using connection to: id: postgres_serving. Host: host.docker.interal, Port: 5432, Schema: serving, Login: ***, Password: ***, extra: {}
[2023-03-21 08:23:51,672] {taskinstance.py:1700} ERROR - Task failed with exception
Traceback (most recent call last):
  File "/home/airflow/.local/lib/python3.7/site-packages/airflow/models/taskinstance.py", line 1329, in _run_raw_task
    self._execute_task_with_callbacks(context)
  File "/home/airflow/.local/lib/python3.7/site-packages/airflow/models/taskinstance.py", line 1455, in _execute_task_with_callbacks
    result = self._execute_task(context, self.task)
  File "/home/airflow/.local/lib/python3.7/site-packages/airflow/models/taskinstance.py", line 1511, in _execute_task
    result = execute_callable(context=context)
  File "/home/airflow/.local/lib/python3.7/site-packages/airflow/providers/postgres/operators/postgres.py", line 69, in execute
    self.hook.run(self.sql, self.autocommit, parameters=self.parameters)
  File "/home/airflow/.local/lib/python3.7/site-packages/airflow/hooks/dbapi.py", line 198, in run
    with closing(self.get_conn()) as conn:
  File "/home/airflow/.local/lib/python3.7/site-packages/airflow/providers/postgres/hooks/postgres.py", line 115, in get_conn
    self.conn = psycopg2.connect(**conn_args)
  File "/home/airflow/.local/lib/python3.7/site-packages/psycopg2/__init__.py", line 122, in connect
    conn = _connect(dsn, connection_factory=connection_factory, **kwasync)
psycopg2.OperationalError: server closed the connection unexpectedly
	This probably means the server terminated abnormally
	before or while processing the request.

[2023-03-21 08:23:51,816] {taskinstance.py:1277} INFO - Marking task as UP_FOR_RETRY. dag_id=querry_postgres_v1.4, task_id=create_querry_postgres_table, execution_date=20230321T075234, start_date=20230321T082347, end_date=20230321T082351
[2023-03-21 08:23:51,862] {standard_task_runner.py:92} ERROR - Failed to execute job 268 for task create_querry_postgres_table
Traceback (most recent call last):
  File "/home/airflow/.local/lib/python3.7/site-packages/airflow/task/task_runner/standard_task_runner.py", line 85, in _start_by_fork
    args.func(args, dag=self.dag)
  File "/home/airflow/.local/lib/python3.7/site-packages/airflow/cli/cli_parser.py", line 48, in command
    return func(*args, **kwargs)
  File "/home/airflow/.local/lib/python3.7/site-packages/airflow/utils/cli.py", line 92, in wrapper
    return f(*args, **kwargs)
  File "/home/airflow/.local/lib/python3.7/site-packages/airflow/cli/commands/task_command.py", line 298, in task_run
    _run_task_by_selected_method(args, dag, ti)
  File "/home/airflow/.local/lib/python3.7/site-packages/airflow/cli/commands/task_command.py", line 107, in _run_task_by_selected_method
    _run_raw_task(args, ti)
  File "/home/airflow/.local/lib/python3.7/site-packages/airflow/cli/commands/task_command.py", line 184, in _run_raw_task
    error_file=args.error_file,
  File "/home/airflow/.local/lib/python3.7/site-packages/airflow/utils/session.py", line 70, in wrapper
    return func(*args, session=session, **kwargs)
  File "/home/airflow/.local/lib/python3.7/site-packages/airflow/models/taskinstance.py", line 1329, in _run_raw_task
    self._execute_task_with_callbacks(context)
  File "/home/airflow/.local/lib/python3.7/site-packages/airflow/models/taskinstance.py", line 1455, in _execute_task_with_callbacks
    result = self._execute_task(context, self.task)
  File "/home/airflow/.local/lib/python3.7/site-packages/airflow/models/taskinstance.py", line 1511, in _execute_task
    result = execute_callable(context=context)
  File "/home/airflow/.local/lib/python3.7/site-packages/airflow/providers/postgres/operators/postgres.py", line 69, in execute
    self.hook.run(self.sql, self.autocommit, parameters=self.parameters)
  File "/home/airflow/.local/lib/python3.7/site-packages/airflow/hooks/dbapi.py", line 198, in run
    with closing(self.get_conn()) as conn:
  File "/home/airflow/.local/lib/python3.7/site-packages/airflow/providers/postgres/hooks/postgres.py", line 115, in get_conn
    self.conn = psycopg2.connect(**conn_args)
  File "/home/airflow/.local/lib/python3.7/site-packages/psycopg2/__init__.py", line 122, in connect
    conn = _connect(dsn, connection_factory=connection_factory, **kwasync)
psycopg2.OperationalError: server closed the connection unexpectedly
	This probably means the server terminated abnormally
	before or while processing the request.

[2023-03-21 08:23:51,899] {local_task_job.py:154} INFO - Task exited with return code 1
[2023-03-21 08:23:52,133] {local_task_job.py:264} INFO - 0 downstream tasks scheduled from follow-on schedule check
