[2023-03-20 18:26:40,661] {taskinstance.py:1032} INFO - Dependencies all met for <TaskInstance: to_posgrest_v4.7.read_and_load_review manual__2023-03-20T18:15:50.093337+00:00 [queued]>
[2023-03-20 18:26:40,700] {taskinstance.py:1032} INFO - Dependencies all met for <TaskInstance: to_posgrest_v4.7.read_and_load_review manual__2023-03-20T18:15:50.093337+00:00 [queued]>
[2023-03-20 18:26:40,701] {taskinstance.py:1238} INFO - 
--------------------------------------------------------------------------------
[2023-03-20 18:26:40,701] {taskinstance.py:1239} INFO - Starting attempt 6 of 7
[2023-03-20 18:26:40,702] {taskinstance.py:1240} INFO - 
--------------------------------------------------------------------------------
[2023-03-20 18:26:40,739] {taskinstance.py:1259} INFO - Executing <Task(PostgresOperator): read_and_load_review> on 2023-03-20 18:15:50.093337+00:00
[2023-03-20 18:26:40,745] {standard_task_runner.py:52} INFO - Started process 20845 to run task
[2023-03-20 18:26:40,753] {standard_task_runner.py:76} INFO - Running: ['***', 'tasks', 'run', 'to_posgrest_v4.7', 'read_and_load_review', 'manual__2023-03-20T18:15:50.093337+00:00', '--job-id', '172', '--raw', '--subdir', 'DAGS_FOLDER/to_postgresql.py', '--cfg-path', '/tmp/tmpj9f7u2bu', '--error-file', '/tmp/tmpaf2m2wyt']
[2023-03-20 18:26:40,755] {standard_task_runner.py:77} INFO - Job 172: Subtask read_and_load_review
[2023-03-20 18:26:41,047] {logging_mixin.py:109} INFO - Running <TaskInstance: to_posgrest_v4.7.read_and_load_review manual__2023-03-20T18:15:50.093337+00:00 [running]> on host 0b4cdb459521
[2023-03-20 18:26:41,357] {taskinstance.py:1426} INFO - Exporting the following env vars:
AIRFLOW_CTX_DAG_OWNER=sakabuana31
AIRFLOW_CTX_DAG_ID=to_posgrest_v4.7
AIRFLOW_CTX_TASK_ID=read_and_load_review
AIRFLOW_CTX_EXECUTION_DATE=2023-03-20T18:15:50.093337+00:00
AIRFLOW_CTX_DAG_RUN_ID=manual__2023-03-20T18:15:50.093337+00:00
[2023-03-20 18:26:41,435] {base.py:79} INFO - Using connection to: id: postgres_localhost. Host: host.docker.internal, Port: 5432, Schema: final, Login: ***, Password: ***, extra: {}
[2023-03-20 18:26:41,511] {dbapi.py:225} INFO - Running statement: 
            CREATE TEMPORARY TABLE temp_review (
                review_id text not null PRIMARY KEY,
                user_id text not null,
                business_id text not null,
                stars int not null,
                useful int not null,
                funny int not null,
                cool int not null,
                text text not null,
                date_values date not null
            );

            COPY temp_review FROM '/opt/***/data/output-csv/checkin_restaurant1.csv' DELIMITER ',' CSV HEADER NULL 'NA';
            INSERT INTO review (review_id, user_id, business_id, stars, useful, funny, cool, text, date_values)
            SELECT review_id, user_id, business_id, stars, useful, funny, cool, text, date_values
            FROM temp_review
            ON CONFLICT (business_id) DO NOTHING;
        , parameters: None
[2023-03-20 18:26:41,521] {taskinstance.py:1700} ERROR - Task failed with exception
Traceback (most recent call last):
  File "/home/airflow/.local/lib/python3.7/site-packages/airflow/models/taskinstance.py", line 1329, in _run_raw_task
    self._execute_task_with_callbacks(context)
  File "/home/airflow/.local/lib/python3.7/site-packages/airflow/models/taskinstance.py", line 1455, in _execute_task_with_callbacks
    result = self._execute_task(context, self.task)
  File "/home/airflow/.local/lib/python3.7/site-packages/airflow/models/taskinstance.py", line 1511, in _execute_task
    result = execute_callable(context=context)
  File "/home/airflow/.local/lib/python3.7/site-packages/airflow/providers/postgres/operators/postgres.py", line 69, in execute
    self.hook.run(self.sql, self.autocommit, parameters=self.parameters)
  File "/home/airflow/.local/lib/python3.7/site-packages/airflow/hooks/dbapi.py", line 205, in run
    self._run_command(cur, sql_statement, parameters)
  File "/home/airflow/.local/lib/python3.7/site-packages/airflow/hooks/dbapi.py", line 229, in _run_command
    cur.execute(sql_statement)
psycopg2.errors.BadCopyFileFormat: missing data for column "business_id"
CONTEXT:  COPY temp_review, line 2: "---kPU91CF4Lq2-WlRu9Lw,20200313"

[2023-03-20 18:26:41,619] {taskinstance.py:1277} INFO - Marking task as UP_FOR_RETRY. dag_id=to_posgrest_v4.7, task_id=read_and_load_review, execution_date=20230320T181550, start_date=20230320T182640, end_date=20230320T182641
[2023-03-20 18:26:41,661] {standard_task_runner.py:92} ERROR - Failed to execute job 172 for task read_and_load_review
Traceback (most recent call last):
  File "/home/airflow/.local/lib/python3.7/site-packages/airflow/task/task_runner/standard_task_runner.py", line 85, in _start_by_fork
    args.func(args, dag=self.dag)
  File "/home/airflow/.local/lib/python3.7/site-packages/airflow/cli/cli_parser.py", line 48, in command
    return func(*args, **kwargs)
  File "/home/airflow/.local/lib/python3.7/site-packages/airflow/utils/cli.py", line 92, in wrapper
    return f(*args, **kwargs)
  File "/home/airflow/.local/lib/python3.7/site-packages/airflow/cli/commands/task_command.py", line 298, in task_run
    _run_task_by_selected_method(args, dag, ti)
  File "/home/airflow/.local/lib/python3.7/site-packages/airflow/cli/commands/task_command.py", line 107, in _run_task_by_selected_method
    _run_raw_task(args, ti)
  File "/home/airflow/.local/lib/python3.7/site-packages/airflow/cli/commands/task_command.py", line 184, in _run_raw_task
    error_file=args.error_file,
  File "/home/airflow/.local/lib/python3.7/site-packages/airflow/utils/session.py", line 70, in wrapper
    return func(*args, session=session, **kwargs)
  File "/home/airflow/.local/lib/python3.7/site-packages/airflow/models/taskinstance.py", line 1329, in _run_raw_task
    self._execute_task_with_callbacks(context)
  File "/home/airflow/.local/lib/python3.7/site-packages/airflow/models/taskinstance.py", line 1455, in _execute_task_with_callbacks
    result = self._execute_task(context, self.task)
  File "/home/airflow/.local/lib/python3.7/site-packages/airflow/models/taskinstance.py", line 1511, in _execute_task
    result = execute_callable(context=context)
  File "/home/airflow/.local/lib/python3.7/site-packages/airflow/providers/postgres/operators/postgres.py", line 69, in execute
    self.hook.run(self.sql, self.autocommit, parameters=self.parameters)
  File "/home/airflow/.local/lib/python3.7/site-packages/airflow/hooks/dbapi.py", line 205, in run
    self._run_command(cur, sql_statement, parameters)
  File "/home/airflow/.local/lib/python3.7/site-packages/airflow/hooks/dbapi.py", line 229, in _run_command
    cur.execute(sql_statement)
psycopg2.errors.BadCopyFileFormat: missing data for column "business_id"
CONTEXT:  COPY temp_review, line 2: "---kPU91CF4Lq2-WlRu9Lw,20200313"

[2023-03-20 18:26:41,692] {local_task_job.py:154} INFO - Task exited with return code 1
[2023-03-20 18:26:41,888] {local_task_job.py:264} INFO - 0 downstream tasks scheduled from follow-on schedule check
