[2023-03-20 16:37:38,756] {taskinstance.py:1032} INFO - Dependencies all met for <TaskInstance: to_posgrest_v4.5.read_and_load_checkin manual__2023-03-20T16:20:18.485887+00:00 [queued]>
[2023-03-20 16:37:38,796] {taskinstance.py:1032} INFO - Dependencies all met for <TaskInstance: to_posgrest_v4.5.read_and_load_checkin manual__2023-03-20T16:20:18.485887+00:00 [queued]>
[2023-03-20 16:37:38,797] {taskinstance.py:1238} INFO - 
--------------------------------------------------------------------------------
[2023-03-20 16:37:38,798] {taskinstance.py:1239} INFO - Starting attempt 8 of 9
[2023-03-20 16:37:38,799] {taskinstance.py:1240} INFO - 
--------------------------------------------------------------------------------
[2023-03-20 16:37:38,838] {taskinstance.py:1259} INFO - Executing <Task(PostgresOperator): read_and_load_checkin> on 2023-03-20 16:20:18.485887+00:00
[2023-03-20 16:37:38,846] {standard_task_runner.py:52} INFO - Started process 14895 to run task
[2023-03-20 16:37:38,856] {standard_task_runner.py:76} INFO - Running: ['***', 'tasks', 'run', 'to_posgrest_v4.5', 'read_and_load_checkin', 'manual__2023-03-20T16:20:18.485887+00:00', '--job-id', '123', '--raw', '--subdir', 'DAGS_FOLDER/to_postgresql.py', '--cfg-path', '/tmp/tmp2utaifmz', '--error-file', '/tmp/tmpogbzqowq']
[2023-03-20 16:37:38,859] {standard_task_runner.py:77} INFO - Job 123: Subtask read_and_load_checkin
[2023-03-20 16:37:39,169] {logging_mixin.py:109} INFO - Running <TaskInstance: to_posgrest_v4.5.read_and_load_checkin manual__2023-03-20T16:20:18.485887+00:00 [running]> on host 0b4cdb459521
[2023-03-20 16:37:39,487] {taskinstance.py:1426} INFO - Exporting the following env vars:
AIRFLOW_CTX_DAG_OWNER=sakabuana31
AIRFLOW_CTX_DAG_ID=to_posgrest_v4.5
AIRFLOW_CTX_TASK_ID=read_and_load_checkin
AIRFLOW_CTX_EXECUTION_DATE=2023-03-20T16:20:18.485887+00:00
AIRFLOW_CTX_DAG_RUN_ID=manual__2023-03-20T16:20:18.485887+00:00
[2023-03-20 16:37:39,567] {base.py:79} INFO - Using connection to: id: postgres_localhost. Host: host.docker.internal, Port: 5432, Schema: final, Login: ***, Password: ***, extra: {}
[2023-03-20 16:37:39,647] {dbapi.py:225} INFO - Running statement: 
            CREATE TEMPORARY TABLE temp_checkin (
                business_id text,
                date_values date PRIMARY KEY
            );

            COPY temp_checkin FROM '/opt/***/data/output-csv/checkin_restaurant.csv' DELIMITER ',' CSV HEADER;
            INSERT INTO checkin (business_id, date_values)
            SELECT DISTINCT ON (date_values) business_id, date_values
            FROM temp_checkin
            ORDER BY date_values
            ON CONFLICT (date_values) DO NOTHING;
        , parameters: None
[2023-03-20 16:37:39,665] {taskinstance.py:1700} ERROR - Task failed with exception
Traceback (most recent call last):
  File "/home/airflow/.local/lib/python3.7/site-packages/airflow/models/taskinstance.py", line 1329, in _run_raw_task
    self._execute_task_with_callbacks(context)
  File "/home/airflow/.local/lib/python3.7/site-packages/airflow/models/taskinstance.py", line 1455, in _execute_task_with_callbacks
    result = self._execute_task(context, self.task)
  File "/home/airflow/.local/lib/python3.7/site-packages/airflow/models/taskinstance.py", line 1511, in _execute_task
    result = execute_callable(context=context)
  File "/home/airflow/.local/lib/python3.7/site-packages/airflow/providers/postgres/operators/postgres.py", line 69, in execute
    self.hook.run(self.sql, self.autocommit, parameters=self.parameters)
  File "/home/airflow/.local/lib/python3.7/site-packages/airflow/hooks/dbapi.py", line 205, in run
    self._run_command(cur, sql_statement, parameters)
  File "/home/airflow/.local/lib/python3.7/site-packages/airflow/hooks/dbapi.py", line 229, in _run_command
    cur.execute(sql_statement)
psycopg2.errors.UndefinedFile: could not open file "/opt/***/data/output-csv/checkin_restaurant.csv" for reading: No such file or directory
HINT:  COPY FROM instructs the PostgreSQL server process to read a file. You may want a client-side facility such as psql's \copy.

[2023-03-20 16:37:39,766] {taskinstance.py:1277} INFO - Marking task as UP_FOR_RETRY. dag_id=to_posgrest_v4.5, task_id=read_and_load_checkin, execution_date=20230320T162018, start_date=20230320T163738, end_date=20230320T163739
[2023-03-20 16:37:39,805] {standard_task_runner.py:92} ERROR - Failed to execute job 123 for task read_and_load_checkin
Traceback (most recent call last):
  File "/home/airflow/.local/lib/python3.7/site-packages/airflow/task/task_runner/standard_task_runner.py", line 85, in _start_by_fork
    args.func(args, dag=self.dag)
  File "/home/airflow/.local/lib/python3.7/site-packages/airflow/cli/cli_parser.py", line 48, in command
    return func(*args, **kwargs)
  File "/home/airflow/.local/lib/python3.7/site-packages/airflow/utils/cli.py", line 92, in wrapper
    return f(*args, **kwargs)
  File "/home/airflow/.local/lib/python3.7/site-packages/airflow/cli/commands/task_command.py", line 298, in task_run
    _run_task_by_selected_method(args, dag, ti)
  File "/home/airflow/.local/lib/python3.7/site-packages/airflow/cli/commands/task_command.py", line 107, in _run_task_by_selected_method
    _run_raw_task(args, ti)
  File "/home/airflow/.local/lib/python3.7/site-packages/airflow/cli/commands/task_command.py", line 184, in _run_raw_task
    error_file=args.error_file,
  File "/home/airflow/.local/lib/python3.7/site-packages/airflow/utils/session.py", line 70, in wrapper
    return func(*args, session=session, **kwargs)
  File "/home/airflow/.local/lib/python3.7/site-packages/airflow/models/taskinstance.py", line 1329, in _run_raw_task
    self._execute_task_with_callbacks(context)
  File "/home/airflow/.local/lib/python3.7/site-packages/airflow/models/taskinstance.py", line 1455, in _execute_task_with_callbacks
    result = self._execute_task(context, self.task)
  File "/home/airflow/.local/lib/python3.7/site-packages/airflow/models/taskinstance.py", line 1511, in _execute_task
    result = execute_callable(context=context)
  File "/home/airflow/.local/lib/python3.7/site-packages/airflow/providers/postgres/operators/postgres.py", line 69, in execute
    self.hook.run(self.sql, self.autocommit, parameters=self.parameters)
  File "/home/airflow/.local/lib/python3.7/site-packages/airflow/hooks/dbapi.py", line 205, in run
    self._run_command(cur, sql_statement, parameters)
  File "/home/airflow/.local/lib/python3.7/site-packages/airflow/hooks/dbapi.py", line 229, in _run_command
    cur.execute(sql_statement)
psycopg2.errors.UndefinedFile: could not open file "/opt/***/data/output-csv/checkin_restaurant.csv" for reading: No such file or directory
HINT:  COPY FROM instructs the PostgreSQL server process to read a file. You may want a client-side facility such as psql's \copy.

[2023-03-20 16:37:39,830] {local_task_job.py:154} INFO - Task exited with return code 1
[2023-03-20 16:37:40,022] {local_task_job.py:264} INFO - 0 downstream tasks scheduled from follow-on schedule check
