[2023-03-20 15:48:21,022] {taskinstance.py:1032} INFO - Dependencies all met for <TaskInstance: to_posgrest_v4.2.read_and_load_user manual__2023-03-20T15:35:27.529831+00:00 [queued]>
[2023-03-20 15:48:21,062] {taskinstance.py:1032} INFO - Dependencies all met for <TaskInstance: to_posgrest_v4.2.read_and_load_user manual__2023-03-20T15:35:27.529831+00:00 [queued]>
[2023-03-20 15:48:21,063] {taskinstance.py:1238} INFO - 
--------------------------------------------------------------------------------
[2023-03-20 15:48:21,063] {taskinstance.py:1239} INFO - Starting attempt 5 of 5
[2023-03-20 15:48:21,064] {taskinstance.py:1240} INFO - 
--------------------------------------------------------------------------------
[2023-03-20 15:48:21,102] {taskinstance.py:1259} INFO - Executing <Task(PostgresOperator): read_and_load_user> on 2023-03-20 15:35:27.529831+00:00
[2023-03-20 15:48:21,108] {standard_task_runner.py:52} INFO - Started process 12054 to run task
[2023-03-20 15:48:21,115] {standard_task_runner.py:76} INFO - Running: ['***', 'tasks', 'run', 'to_posgrest_v4.2', 'read_and_load_user', 'manual__2023-03-20T15:35:27.529831+00:00', '--job-id', '65', '--raw', '--subdir', 'DAGS_FOLDER/to_postgresql.py', '--cfg-path', '/tmp/tmptf_5n668', '--error-file', '/tmp/tmp49ne7tsw']
[2023-03-20 15:48:21,118] {standard_task_runner.py:77} INFO - Job 65: Subtask read_and_load_user
[2023-03-20 15:48:21,418] {logging_mixin.py:109} INFO - Running <TaskInstance: to_posgrest_v4.2.read_and_load_user manual__2023-03-20T15:35:27.529831+00:00 [running]> on host 0b4cdb459521
[2023-03-20 15:48:21,731] {taskinstance.py:1426} INFO - Exporting the following env vars:
AIRFLOW_CTX_DAG_OWNER=sakabuana31
AIRFLOW_CTX_DAG_ID=to_posgrest_v4.2
AIRFLOW_CTX_TASK_ID=read_and_load_user
AIRFLOW_CTX_EXECUTION_DATE=2023-03-20T15:35:27.529831+00:00
AIRFLOW_CTX_DAG_RUN_ID=manual__2023-03-20T15:35:27.529831+00:00
[2023-03-20 15:48:21,810] {base.py:79} INFO - Using connection to: id: postgres_localhost. Host: host.docker.internal, Port: 5432, Schema: final, Login: ***, Password: ***, extra: {}
[2023-03-20 15:48:21,902] {dbapi.py:225} INFO - Running statement: 
            CREATE TEMPORARY TABLE temp_user1 (
                user_id text PRIMARY KEY,
                name text,
                review_count text,
                useful int,
                funny int,
                cool int,
                elite int,
                friends text,
                fans text,
                average_stars int,
                yelping_since_values date
            );

            COPY temp_user1 FROM '/opt/***/data/output-csv/user_restaurant.csv' DELIMITER ',' CSV HEADER;
            INSERT INTO user1 (user_id, name, review_count, useful, funny, cool, elite, friends, fans, average_stars, yelping_since_values)
            SELECT user_id, name, review_count, useful, funny, cool, elite, friends, fans, average_stars, yelping_since_values
            FROM temp_user1
            ON CONFLICT (user_id) DO NOTHING;
        , parameters: None
[2023-03-20 15:48:21,919] {taskinstance.py:1700} ERROR - Task failed with exception
Traceback (most recent call last):
  File "/home/airflow/.local/lib/python3.7/site-packages/airflow/models/taskinstance.py", line 1329, in _run_raw_task
    self._execute_task_with_callbacks(context)
  File "/home/airflow/.local/lib/python3.7/site-packages/airflow/models/taskinstance.py", line 1455, in _execute_task_with_callbacks
    result = self._execute_task(context, self.task)
  File "/home/airflow/.local/lib/python3.7/site-packages/airflow/models/taskinstance.py", line 1511, in _execute_task
    result = execute_callable(context=context)
  File "/home/airflow/.local/lib/python3.7/site-packages/airflow/providers/postgres/operators/postgres.py", line 69, in execute
    self.hook.run(self.sql, self.autocommit, parameters=self.parameters)
  File "/home/airflow/.local/lib/python3.7/site-packages/airflow/hooks/dbapi.py", line 205, in run
    self._run_command(cur, sql_statement, parameters)
  File "/home/airflow/.local/lib/python3.7/site-packages/airflow/hooks/dbapi.py", line 229, in _run_command
    cur.execute(sql_statement)
psycopg2.errors.InvalidTextRepresentation: invalid input syntax for type integer: "5.0"
CONTEXT:  COPY temp_user1, line 2, column average_stars: "5.0"

[2023-03-20 15:48:22,017] {taskinstance.py:1277} INFO - Marking task as FAILED. dag_id=to_posgrest_v4.2, task_id=read_and_load_user, execution_date=20230320T153527, start_date=20230320T154821, end_date=20230320T154822
[2023-03-20 15:48:22,057] {standard_task_runner.py:92} ERROR - Failed to execute job 65 for task read_and_load_user
Traceback (most recent call last):
  File "/home/airflow/.local/lib/python3.7/site-packages/airflow/task/task_runner/standard_task_runner.py", line 85, in _start_by_fork
    args.func(args, dag=self.dag)
  File "/home/airflow/.local/lib/python3.7/site-packages/airflow/cli/cli_parser.py", line 48, in command
    return func(*args, **kwargs)
  File "/home/airflow/.local/lib/python3.7/site-packages/airflow/utils/cli.py", line 92, in wrapper
    return f(*args, **kwargs)
  File "/home/airflow/.local/lib/python3.7/site-packages/airflow/cli/commands/task_command.py", line 298, in task_run
    _run_task_by_selected_method(args, dag, ti)
  File "/home/airflow/.local/lib/python3.7/site-packages/airflow/cli/commands/task_command.py", line 107, in _run_task_by_selected_method
    _run_raw_task(args, ti)
  File "/home/airflow/.local/lib/python3.7/site-packages/airflow/cli/commands/task_command.py", line 184, in _run_raw_task
    error_file=args.error_file,
  File "/home/airflow/.local/lib/python3.7/site-packages/airflow/utils/session.py", line 70, in wrapper
    return func(*args, session=session, **kwargs)
  File "/home/airflow/.local/lib/python3.7/site-packages/airflow/models/taskinstance.py", line 1329, in _run_raw_task
    self._execute_task_with_callbacks(context)
  File "/home/airflow/.local/lib/python3.7/site-packages/airflow/models/taskinstance.py", line 1455, in _execute_task_with_callbacks
    result = self._execute_task(context, self.task)
  File "/home/airflow/.local/lib/python3.7/site-packages/airflow/models/taskinstance.py", line 1511, in _execute_task
    result = execute_callable(context=context)
  File "/home/airflow/.local/lib/python3.7/site-packages/airflow/providers/postgres/operators/postgres.py", line 69, in execute
    self.hook.run(self.sql, self.autocommit, parameters=self.parameters)
  File "/home/airflow/.local/lib/python3.7/site-packages/airflow/hooks/dbapi.py", line 205, in run
    self._run_command(cur, sql_statement, parameters)
  File "/home/airflow/.local/lib/python3.7/site-packages/airflow/hooks/dbapi.py", line 229, in _run_command
    cur.execute(sql_statement)
psycopg2.errors.InvalidTextRepresentation: invalid input syntax for type integer: "5.0"
CONTEXT:  COPY temp_user1, line 2, column average_stars: "5.0"

[2023-03-20 15:48:22,099] {local_task_job.py:154} INFO - Task exited with return code 1
[2023-03-20 15:48:22,292] {local_task_job.py:264} INFO - 0 downstream tasks scheduled from follow-on schedule check
