[2023-03-21 13:16:42,567] {taskinstance.py:1032} INFO - Dependencies all met for <TaskInstance: querry_postgres_v1.4.insert_querry_postgres_table manual__2023-03-21T13:13:41.480553+00:00 [queued]>
[2023-03-21 13:16:42,609] {taskinstance.py:1032} INFO - Dependencies all met for <TaskInstance: querry_postgres_v1.4.insert_querry_postgres_table manual__2023-03-21T13:13:41.480553+00:00 [queued]>
[2023-03-21 13:16:42,611] {taskinstance.py:1238} INFO - 
--------------------------------------------------------------------------------
[2023-03-21 13:16:42,612] {taskinstance.py:1239} INFO - Starting attempt 2 of 3
[2023-03-21 13:16:42,612] {taskinstance.py:1240} INFO - 
--------------------------------------------------------------------------------
[2023-03-21 13:16:42,651] {taskinstance.py:1259} INFO - Executing <Task(PostgresOperator): insert_querry_postgres_table> on 2023-03-21 13:13:41.480553+00:00
[2023-03-21 13:16:42,658] {standard_task_runner.py:52} INFO - Started process 12131 to run task
[2023-03-21 13:16:42,666] {standard_task_runner.py:76} INFO - Running: ['***', 'tasks', 'run', 'querry_postgres_v1.4', 'insert_querry_postgres_table', 'manual__2023-03-21T13:13:41.480553+00:00', '--job-id', '291', '--raw', '--subdir', 'DAGS_FOLDER/querry_posgresql.py', '--cfg-path', '/tmp/tmp7bqwxlhp', '--error-file', '/tmp/tmpbm0x9eth']
[2023-03-21 13:16:42,669] {standard_task_runner.py:77} INFO - Job 291: Subtask insert_querry_postgres_table
[2023-03-21 13:16:42,986] {logging_mixin.py:109} INFO - Running <TaskInstance: querry_postgres_v1.4.insert_querry_postgres_table manual__2023-03-21T13:13:41.480553+00:00 [running]> on host 0b4cdb459521
[2023-03-21 13:16:43,305] {taskinstance.py:1426} INFO - Exporting the following env vars:
AIRFLOW_CTX_DAG_OWNER=sakabuana31
AIRFLOW_CTX_DAG_ID=querry_postgres_v1.4
AIRFLOW_CTX_TASK_ID=insert_querry_postgres_table
AIRFLOW_CTX_EXECUTION_DATE=2023-03-21T13:13:41.480553+00:00
AIRFLOW_CTX_DAG_RUN_ID=manual__2023-03-21T13:13:41.480553+00:00
[2023-03-21 13:16:43,384] {base.py:79} INFO - Using connection to: id: postgres_serving. Host: host.docker.internal, Port: 5432, Schema: serving, Login: ***, Password: ***, extra: {}
[2023-03-21 13:16:43,465] {dbapi.py:225} INFO - Running statement: 
            INSERT INTO serving_table_review (date, status_temp, status_preci, business_id, business_name, stars, date_values)
            SELECT date_values, status_temp, status_preci, business_id, business_name, stars, date_values
            FROM task_instance.xcom_pull(task_ids='task2')
        , parameters: None
[2023-03-21 13:16:43,471] {taskinstance.py:1700} ERROR - Task failed with exception
Traceback (most recent call last):
  File "/home/airflow/.local/lib/python3.7/site-packages/airflow/models/taskinstance.py", line 1329, in _run_raw_task
    self._execute_task_with_callbacks(context)
  File "/home/airflow/.local/lib/python3.7/site-packages/airflow/models/taskinstance.py", line 1455, in _execute_task_with_callbacks
    result = self._execute_task(context, self.task)
  File "/home/airflow/.local/lib/python3.7/site-packages/airflow/models/taskinstance.py", line 1511, in _execute_task
    result = execute_callable(context=context)
  File "/home/airflow/.local/lib/python3.7/site-packages/airflow/providers/postgres/operators/postgres.py", line 69, in execute
    self.hook.run(self.sql, self.autocommit, parameters=self.parameters)
  File "/home/airflow/.local/lib/python3.7/site-packages/airflow/hooks/dbapi.py", line 205, in run
    self._run_command(cur, sql_statement, parameters)
  File "/home/airflow/.local/lib/python3.7/site-packages/airflow/hooks/dbapi.py", line 229, in _run_command
    cur.execute(sql_statement)
psycopg2.errors.UndefinedColumn: column "task_ids" does not exist
LINE 4:             FROM task_instance.xcom_pull(task_ids='task2')
                                                 ^

[2023-03-21 13:16:43,569] {taskinstance.py:1277} INFO - Marking task as UP_FOR_RETRY. dag_id=querry_postgres_v1.4, task_id=insert_querry_postgres_table, execution_date=20230321T131341, start_date=20230321T131642, end_date=20230321T131643
[2023-03-21 13:16:43,611] {standard_task_runner.py:92} ERROR - Failed to execute job 291 for task insert_querry_postgres_table
Traceback (most recent call last):
  File "/home/airflow/.local/lib/python3.7/site-packages/airflow/task/task_runner/standard_task_runner.py", line 85, in _start_by_fork
    args.func(args, dag=self.dag)
  File "/home/airflow/.local/lib/python3.7/site-packages/airflow/cli/cli_parser.py", line 48, in command
    return func(*args, **kwargs)
  File "/home/airflow/.local/lib/python3.7/site-packages/airflow/utils/cli.py", line 92, in wrapper
    return f(*args, **kwargs)
  File "/home/airflow/.local/lib/python3.7/site-packages/airflow/cli/commands/task_command.py", line 298, in task_run
    _run_task_by_selected_method(args, dag, ti)
  File "/home/airflow/.local/lib/python3.7/site-packages/airflow/cli/commands/task_command.py", line 107, in _run_task_by_selected_method
    _run_raw_task(args, ti)
  File "/home/airflow/.local/lib/python3.7/site-packages/airflow/cli/commands/task_command.py", line 184, in _run_raw_task
    error_file=args.error_file,
  File "/home/airflow/.local/lib/python3.7/site-packages/airflow/utils/session.py", line 70, in wrapper
    return func(*args, session=session, **kwargs)
  File "/home/airflow/.local/lib/python3.7/site-packages/airflow/models/taskinstance.py", line 1329, in _run_raw_task
    self._execute_task_with_callbacks(context)
  File "/home/airflow/.local/lib/python3.7/site-packages/airflow/models/taskinstance.py", line 1455, in _execute_task_with_callbacks
    result = self._execute_task(context, self.task)
  File "/home/airflow/.local/lib/python3.7/site-packages/airflow/models/taskinstance.py", line 1511, in _execute_task
    result = execute_callable(context=context)
  File "/home/airflow/.local/lib/python3.7/site-packages/airflow/providers/postgres/operators/postgres.py", line 69, in execute
    self.hook.run(self.sql, self.autocommit, parameters=self.parameters)
  File "/home/airflow/.local/lib/python3.7/site-packages/airflow/hooks/dbapi.py", line 205, in run
    self._run_command(cur, sql_statement, parameters)
  File "/home/airflow/.local/lib/python3.7/site-packages/airflow/hooks/dbapi.py", line 229, in _run_command
    cur.execute(sql_statement)
psycopg2.errors.UndefinedColumn: column "task_ids" does not exist
LINE 4:             FROM task_instance.xcom_pull(task_ids='task2')
                                                 ^

[2023-03-21 13:16:43,668] {local_task_job.py:154} INFO - Task exited with return code 1
[2023-03-21 13:16:43,859] {local_task_job.py:264} INFO - 0 downstream tasks scheduled from follow-on schedule check
